{"time":"{{.timestamp_iso}}","resourceId":"/SUBSCRIPTIONS/12CABCB4-86E8-404F-A3D2-1DC9982F45CA/RESOURCEGROUPS/TEST-RG/PROVIDERS/{{.Domains}}/SITES/TEST-FUNCTION","category":"FunctionAppLogs","operationName":"{{.Domains}}/sites/functions/log","level":"Error","location":"East US","properties":{"appName":"mbranca-test-function","roleInstance":"54108609-638217294083255145","message":"Executed {{.Domains}} (Failed, Id=3a4b2e78-0549-4ebc-ba4c-ee9a6bc9a04e, Duration=16ms)","category":"{{.Domains}}","hostVersion":"{{.IPs}}","functionInvocationId":"3a4b2e78-0549-4ebc-ba4c-ee9a6bc9a04e","functionName":"{{.Domains}}","hostInstanceId":"8699ec76-436a-43e2-a811-371c8e1472d7","level":"Error","levelId":4,"processId":64,"exceptionDetails":"{{.Domains}} : Exception while executing function: {{.Domains}} ---> {{.Domains}} : Result: Failure\nException: Exception: Ka-booom!\nStack:   File \"/azure-functions-host/workers/python/3.9/LINUX/X64/azure_functions_worker/{{.Domains}}\", line 479, in _handle__invocation_request\n    call_result = await self._{{.Domains}}_in_executor(\n  File \"/usr/local/lib/python3.9/concurrent/futures/{{.Domains}}\", line 58, in run\n    result = {{.Domains}}(*{{.Domains}}, **{{.Domains}})\n  File \"/azure-functions-host/workers/python/3.9/LINUX/X64/azure_functions_worker/{{.Domains}}\", line 752, in _run_sync_func\n    return {{.Domains}}_sync_invocation_wrapper(context,\n  File \"/azure-functions-host/workers/python/3.9/LINUX/X64/azure_functions_worker/{{.Domains}}\", line 215, in _raw_invocation_wrapper\n    result = function(**args)\n  File \"/home/site/wwwroot/hello/__init__.py\", line 22, in main\n    raise Exception(\"Ka-booom!\")\n\n   at {{.Domains}}()\n   at async {{.Domains}}(Object[] parameters,FunctionInvocationContext context) at /src/azure-functions-host/src/{{.Domains}}/Description/Workers/{{.Domains}} : 101\n   at {{.Domains}}()\n   at async {{.Domains}}(Object[] parameters) at /src/azure-functions-host/src/{{.Domains}}/Description/{{.Domains}} : 82\n   at {{.Domains}}()\n   at async {{.Domains}}[T](Task`1 src) at /src/azure-functions-host/src/{{.Domains}}/Description/{{.Domains}} : 225\n   at {{.Domains}}()\n   at async {{.Domains}}`{{.Domains}}[TReflected,TReturnValue](Object instance,Object[] arguments) at D:\\a\\_work\\1\\s\\src\\{{.Domains}}\\Executors\\{{.Domains}} : 52\n   at {{.Domains}}()\n   at async {{.Domains}}(IFunctionInvoker invoker,ParameterHelper parameterHelper,CancellationTokenSource timeoutTokenSource,CancellationTokenSource functionCancellationTokenSource,Boolean throwOnTimeout,TimeSpan timerInterval,IFunctionInstance instance) at D:\\a\\_work\\1\\s\\src\\{{.Domains}}\\Executors\\{{.Domains}} : 581\n   at {{.Domains}}()\n   at async {{.Domains}}(IFunctionInstanceEx instance,ParameterHelper parameterHelper,ILogger logger,CancellationTokenSource functionCancellationTokenSource) at D:\\a\\_work\\1\\s\\src\\{{.Domains}}\\Executors\\{{.Domains}} : 527\n   at {{.Domains}}()\n   at async {{.Domains}}(IFunctionInstanceEx instance,FunctionStartedMessage message,FunctionInstanceLogEntry instanceLogEntry,ParameterHelper parameterHelper,ILogger logger,CancellationToken cancellationToken) at D:\\a\\_work\\1\\s\\src\\{{.Domains}}\\Executors\\{{.Domains}} : 306\n   End of inner exception\n   at {{.Domains}}()\n   at async {{.Domains}}(IFunctionInstanceEx instance,FunctionStartedMessage message,FunctionInstanceLogEntry instanceLogEntry,ParameterHelper parameterHelper,ILogger logger,CancellationToken cancellationToken) at D:\\a\\_work\\1\\s\\src\\{{.Domains}}\\Executors\\{{.Domains}} : 352\n   at {{.Domains}}()\n   at async {{.Domains}}(IFunctionInstance functionInstance,CancellationToken cancellationToken) at D:\\a\\_work\\1\\s\\src\\{{.Domains}}\\Executors\\{{.Domains}} : 108","exceptionMessage":"Result: Failure\nException: Exception: Ka-booom!\nStack:   File \"/azure-functions-host/workers/python/3.9/LINUX/X64/azure_functions_worker/{{.Domains}}\", line 479, in _handle__invocation_request\n    call_result = await self._{{.Domains}}_in_executor(\n  File \"/usr/local/lib/python3.9/concurrent/futures/{{.Domains}}\", line 58, in run\n    result = {{.Domains}}(*{{.Domains}}, **{{.Domains}})\n  File \"/azure-functions-host/workers/python/3.9/LINUX/X64/azure_functions_worker/{{.Domains}}\", line 752, in _run_sync_func\n    return {{.Domains}}_sync_invocation_wrapper(context,\n  File \"/azure-functions-host/workers/python/3.9/LINUX/X64/azure_functions_worker/{{.Domains}}\", line 215, in _raw_invocation_wrapper\n    result = function(**args)\n  File \"/home/site/wwwroot/hello/__init__.py\", line 22, in main\n    raise Exception(\"Ka-booom!\")\n","exceptionType":"{{.Domains}}","eventId":3,"eventName":"FunctionCompleted"}}
---EVENT_DELIMITER---
{"time":"{{.timestamp_iso}}","resourceId":"/SUBSCRIPTIONS/12CABCB4-86E8-404F-A3D2-1DC9982F45CA/RESOURCEGROUPS/TEST-RG/PROVIDERS/{{.Domains}}/SITES/TEST-FUNCTION","category":"FunctionAppLogs","operationName":"{{.Domains}}/sites/functions/log","level":"Informational","location":"East US","properties":{"appName":"test-function","roleInstance":"54108609-638204200593759681","message":"Executing {{.Domains}} (Reason=This function was programmatically called via the host APIs., Id=d878e365-b3d6-4796-9292-7500acd0c677)","category":"{{.Domains}}","hostVersion":"{{.IPs}}","functionInvocationId":"d878e365-b3d6-4796-9292-7500acd0c677","functionName":"{{.Domains}}","hostInstanceId":"bb84c437-4c26-4d0b-a06d-7fc2f16976e3","level":"Information","levelId":2,"processId":67,"eventId":1,"eventName":"FunctionStarted"}}